[Tue Mar 15 10:52:13.150428 2022] [wsgi:error] [pid 809976] [remote 46.28.73.122:31733] Not Found: /assets/favicon.ico
[Tue Mar 15 10:54:21.725217 2022] [wsgi:error] [pid 809976] [remote 46.28.73.122:31744] Not Found: /assets/favicon.ico
[Tue Mar 15 10:54:24.219380 2022] [wsgi:error] [pid 809976] [remote 46.28.73.122:31738] Internal Server Error: /category/cisco
[Tue Mar 15 10:54:24.219453 2022] [wsgi:error] [pid 809976] [remote 46.28.73.122:31738] Traceback (most recent call last):
[Tue Mar 15 10:54:24.219488 2022] [wsgi:error] [pid 809976] [remote 46.28.73.122:31738]   File "/django-project/venv/lib/python3.9/site-packages/django/template/backends/django.py", line 62, in render
[Tue Mar 15 10:54:24.219507 2022] [wsgi:error] [pid 809976] [remote 46.28.73.122:31738]     return self.template.render(context)
[Tue Mar 15 10:54:24.219526 2022] [wsgi:error] [pid 809976] [remote 46.28.73.122:31738]   File "/django-project/venv/lib/python3.9/site-packages/django/template/base.py", line 175, in render
[Tue Mar 15 10:54:24.219546 2022] [wsgi:error] [pid 809976] [remote 46.28.73.122:31738]     return self._render(context)
[Tue Mar 15 10:54:24.219566 2022] [wsgi:error] [pid 809976] [remote 46.28.73.122:31738]   File "/django-project/venv/lib/python3.9/site-packages/django/template/base.py", line 167, in _render
[Tue Mar 15 10:54:24.219583 2022] [wsgi:error] [pid 809976] [remote 46.28.73.122:31738]     return self.nodelist.render(context)
[Tue Mar 15 10:54:24.219600 2022] [wsgi:error] [pid 809976] [remote 46.28.73.122:31738]   File "/django-project/venv/lib/python3.9/site-packages/django/template/base.py", line 1000, in render
[Tue Mar 15 10:54:24.219617 2022] [wsgi:error] [pid 809976] [remote 46.28.73.122:31738]     return SafeString("".join([node.render_annotated(context) for node in self]))
[Tue Mar 15 10:54:24.219636 2022] [wsgi:error] [pid 809976] [remote 46.28.73.122:31738]   File "/django-project/venv/lib/python3.9/site-packages/django/template/base.py", line 1000, in <listcomp>
[Tue Mar 15 10:54:24.219651 2022] [wsgi:error] [pid 809976] [remote 46.28.73.122:31738]     return SafeString("".join([node.render_annotated(context) for node in self]))
[Tue Mar 15 10:54:24.219665 2022] [wsgi:error] [pid 809976] [remote 46.28.73.122:31738]   File "/django-project/venv/lib/python3.9/site-packages/django/template/base.py", line 958, in render_annotated
[Tue Mar 15 10:54:24.219679 2022] [wsgi:error] [pid 809976] [remote 46.28.73.122:31738]     return self.render(context)
[Tue Mar 15 10:54:24.219693 2022] [wsgi:error] [pid 809976] [remote 46.28.73.122:31738]   File "/django-project/venv/lib/python3.9/site-packages/django/template/loader_tags.py", line 132, in render
[Tue Mar 15 10:54:24.219707 2022] [wsgi:error] [pid 809976] [remote 46.28.73.122:31738]     compiled_parent = self.get_parent(context)
[Tue Mar 15 10:54:24.219721 2022] [wsgi:error] [pid 809976] [remote 46.28.73.122:31738]   File "/django-project/venv/lib/python3.9/site-packages/django/template/loader_tags.py", line 129, in get_parent
[Tue Mar 15 10:54:24.219735 2022] [wsgi:error] [pid 809976] [remote 46.28.73.122:31738]     return self.find_template(parent, context)
[Tue Mar 15 10:54:24.219749 2022] [wsgi:error] [pid 809976] [remote 46.28.73.122:31738]   File "/django-project/venv/lib/python3.9/site-packages/django/template/loader_tags.py", line 107, in find_template
[Tue Mar 15 10:54:24.219764 2022] [wsgi:error] [pid 809976] [remote 46.28.73.122:31738]     template, origin = context.template.engine.find_template(
[Tue Mar 15 10:54:24.219780 2022] [wsgi:error] [pid 809976] [remote 46.28.73.122:31738]   File "/django-project/venv/lib/python3.9/site-packages/django/template/engine.py", line 162, in find_template
[Tue Mar 15 10:54:24.219798 2022] [wsgi:error] [pid 809976] [remote 46.28.73.122:31738]     raise TemplateDoesNotExist(name, tried=tried)
[Tue Mar 15 10:54:24.219818 2022] [wsgi:error] [pid 809976] [remote 46.28.73.122:31738] django.template.exceptions.TemplateDoesNotExist: blog/base.html 
[Tue Mar 15 10:54:24.219839 2022] [wsgi:error] [pid 809976] [remote 46.28.73.122:31738] 
[Tue Mar 15 10:54:24.219890 2022] [wsgi:error] [pid 809976] [remote 46.28.73.122:31738] The above exception was the direct cause of the following exception:
[Tue Mar 15 10:54:24.219909 2022] [wsgi:error] [pid 809976] [remote 46.28.73.122:31738] 
[Tue Mar 15 10:54:24.219924 2022] [wsgi:error] [pid 809976] [remote 46.28.73.122:31738] Traceback (most recent call last):
[Tue Mar 15 10:54:24.219942 2022] [wsgi:error] [pid 809976] [remote 46.28.73.122:31738]   File "/django-project/venv/lib/python3.9/site-packages/django/core/handlers/exception.py", line 55, in inner
[Tue Mar 15 10:54:24.219962 2022] [wsgi:error] [pid 809976] [remote 46.28.73.122:31738]     response = get_response(request)
[Tue Mar 15 10:54:24.219976 2022] [wsgi:error] [pid 809976] [remote 46.28.73.122:31738]   File "/django-project/venv/lib/python3.9/site-packages/django/core/handlers/base.py", line 220, in _get_response
[Tue Mar 15 10:54:24.219990 2022] [wsgi:error] [pid 809976] [remote 46.28.73.122:31738]     response = response.render()
[Tue Mar 15 10:54:24.220004 2022] [wsgi:error] [pid 809976] [remote 46.28.73.122:31738]   File "/django-project/venv/lib/python3.9/site-packages/django/template/response.py", line 114, in render
[Tue Mar 15 10:54:24.220018 2022] [wsgi:error] [pid 809976] [remote 46.28.73.122:31738]     self.content = self.rendered_content
[Tue Mar 15 10:54:24.220032 2022] [wsgi:error] [pid 809976] [remote 46.28.73.122:31738]   File "/django-project/venv/lib/python3.9/site-packages/django/template/response.py", line 92, in rendered_content
[Tue Mar 15 10:54:24.220046 2022] [wsgi:error] [pid 809976] [remote 46.28.73.122:31738]     return template.render(context, self._request)
[Tue Mar 15 10:54:24.220060 2022] [wsgi:error] [pid 809976] [remote 46.28.73.122:31738]   File "/django-project/venv/lib/python3.9/site-packages/django/template/backends/django.py", line 64, in render
[Tue Mar 15 10:54:24.220075 2022] [wsgi:error] [pid 809976] [remote 46.28.73.122:31738]     reraise(exc, self.backend)
[Tue Mar 15 10:54:24.220088 2022] [wsgi:error] [pid 809976] [remote 46.28.73.122:31738]   File "/django-project/venv/lib/python3.9/site-packages/django/template/backends/django.py", line 85, in reraise
[Tue Mar 15 10:54:24.220103 2022] [wsgi:error] [pid 809976] [remote 46.28.73.122:31738]     raise new from exc
[Tue Mar 15 10:54:24.220116 2022] [wsgi:error] [pid 809976] [remote 46.28.73.122:31738] django.template.exceptions.TemplateDoesNotExist: blog/base.html 
[Tue Mar 15 10:55:02.754609 2022] [wsgi:error] [pid 809976] [remote 46.28.73.122:31749] Internal Server Error: /category/cisco
[Tue Mar 15 10:55:02.754706 2022] [wsgi:error] [pid 809976] [remote 46.28.73.122:31749] Traceback (most recent call last):
[Tue Mar 15 10:55:02.754721 2022] [wsgi:error] [pid 809976] [remote 46.28.73.122:31749]   File "/django-project/venv/lib/python3.9/site-packages/django/template/backends/django.py", line 62, in render
[Tue Mar 15 10:55:02.754736 2022] [wsgi:error] [pid 809976] [remote 46.28.73.122:31749]     return self.template.render(context)
[Tue Mar 15 10:55:02.754750 2022] [wsgi:error] [pid 809976] [remote 46.28.73.122:31749]   File "/django-project/venv/lib/python3.9/site-packages/django/template/base.py", line 175, in render
[Tue Mar 15 10:55:02.754765 2022] [wsgi:error] [pid 809976] [remote 46.28.73.122:31749]     return self._render(context)
[Tue Mar 15 10:55:02.754779 2022] [wsgi:error] [pid 809976] [remote 46.28.73.122:31749]   File "/django-project/venv/lib/python3.9/site-packages/django/template/base.py", line 167, in _render
[Tue Mar 15 10:55:02.754793 2022] [wsgi:error] [pid 809976] [remote 46.28.73.122:31749]     return self.nodelist.render(context)
[Tue Mar 15 10:55:02.754807 2022] [wsgi:error] [pid 809976] [remote 46.28.73.122:31749]   File "/django-project/venv/lib/python3.9/site-packages/django/template/base.py", line 1000, in render
[Tue Mar 15 10:55:02.754821 2022] [wsgi:error] [pid 809976] [remote 46.28.73.122:31749]     return SafeString("".join([node.render_annotated(context) for node in self]))
[Tue Mar 15 10:55:02.754835 2022] [wsgi:error] [pid 809976] [remote 46.28.73.122:31749]   File "/django-project/venv/lib/python3.9/site-packages/django/template/base.py", line 1000, in <listcomp>
[Tue Mar 15 10:55:02.754872 2022] [wsgi:error] [pid 809976] [remote 46.28.73.122:31749]     return SafeString("".join([node.render_annotated(context) for node in self]))
[Tue Mar 15 10:55:02.754886 2022] [wsgi:error] [pid 809976] [remote 46.28.73.122:31749]   File "/django-project/venv/lib/python3.9/site-packages/django/template/base.py", line 958, in render_annotated
[Tue Mar 15 10:55:02.754900 2022] [wsgi:error] [pid 809976] [remote 46.28.73.122:31749]     return self.render(context)
[Tue Mar 15 10:55:02.754914 2022] [wsgi:error] [pid 809976] [remote 46.28.73.122:31749]   File "/django-project/venv/lib/python3.9/site-packages/django/template/loader_tags.py", line 132, in render
[Tue Mar 15 10:55:02.754928 2022] [wsgi:error] [pid 809976] [remote 46.28.73.122:31749]     compiled_parent = self.get_parent(context)
[Tue Mar 15 10:55:02.754942 2022] [wsgi:error] [pid 809976] [remote 46.28.73.122:31749]   File "/django-project/venv/lib/python3.9/site-packages/django/template/loader_tags.py", line 129, in get_parent
[Tue Mar 15 10:55:02.754956 2022] [wsgi:error] [pid 809976] [remote 46.28.73.122:31749]     return self.find_template(parent, context)
[Tue Mar 15 10:55:02.754970 2022] [wsgi:error] [pid 809976] [remote 46.28.73.122:31749]   File "/django-project/venv/lib/python3.9/site-packages/django/template/loader_tags.py", line 107, in find_template
[Tue Mar 15 10:55:02.754985 2022] [wsgi:error] [pid 809976] [remote 46.28.73.122:31749]     template, origin = context.template.engine.find_template(
[Tue Mar 15 10:55:02.754998 2022] [wsgi:error] [pid 809976] [remote 46.28.73.122:31749]   File "/django-project/venv/lib/python3.9/site-packages/django/template/engine.py", line 162, in find_template
[Tue Mar 15 10:55:02.755013 2022] [wsgi:error] [pid 809976] [remote 46.28.73.122:31749]     raise TemplateDoesNotExist(name, tried=tried)
[Tue Mar 15 10:55:02.755026 2022] [wsgi:error] [pid 809976] [remote 46.28.73.122:31749] django.template.exceptions.TemplateDoesNotExist: blog/base.html 
[Tue Mar 15 10:55:02.755040 2022] [wsgi:error] [pid 809976] [remote 46.28.73.122:31749] 
[Tue Mar 15 10:55:02.755054 2022] [wsgi:error] [pid 809976] [remote 46.28.73.122:31749] The above exception was the direct cause of the following exception:
[Tue Mar 15 10:55:02.755068 2022] [wsgi:error] [pid 809976] [remote 46.28.73.122:31749] 
[Tue Mar 15 10:55:02.755081 2022] [wsgi:error] [pid 809976] [remote 46.28.73.122:31749] Traceback (most recent call last):
[Tue Mar 15 10:55:02.755095 2022] [wsgi:error] [pid 809976] [remote 46.28.73.122:31749]   File "/django-project/venv/lib/python3.9/site-packages/django/core/handlers/exception.py", line 55, in inner
[Tue Mar 15 10:55:02.755109 2022] [wsgi:error] [pid 809976] [remote 46.28.73.122:31749]     response = get_response(request)
[Tue Mar 15 10:55:02.755123 2022] [wsgi:error] [pid 809976] [remote 46.28.73.122:31749]   File "/django-project/venv/lib/python3.9/site-packages/django/core/handlers/base.py", line 220, in _get_response
[Tue Mar 15 10:55:02.755137 2022] [wsgi:error] [pid 809976] [remote 46.28.73.122:31749]     response = response.render()
[Tue Mar 15 10:55:02.755151 2022] [wsgi:error] [pid 809976] [remote 46.28.73.122:31749]   File "/django-project/venv/lib/python3.9/site-packages/django/template/response.py", line 114, in render
[Tue Mar 15 10:55:02.755165 2022] [wsgi:error] [pid 809976] [remote 46.28.73.122:31749]     self.content = self.rendered_content
[Tue Mar 15 10:55:02.755179 2022] [wsgi:error] [pid 809976] [remote 46.28.73.122:31749]   File "/django-project/venv/lib/python3.9/site-packages/django/template/response.py", line 92, in rendered_content
[Tue Mar 15 10:55:02.755193 2022] [wsgi:error] [pid 809976] [remote 46.28.73.122:31749]     return template.render(context, self._request)
[Tue Mar 15 10:55:02.755207 2022] [wsgi:error] [pid 809976] [remote 46.28.73.122:31749]   File "/django-project/venv/lib/python3.9/site-packages/django/template/backends/django.py", line 64, in render
[Tue Mar 15 10:55:02.755234 2022] [wsgi:error] [pid 809976] [remote 46.28.73.122:31749]     reraise(exc, self.backend)
[Tue Mar 15 10:55:02.755248 2022] [wsgi:error] [pid 809976] [remote 46.28.73.122:31749]   File "/django-project/venv/lib/python3.9/site-packages/django/template/backends/django.py", line 85, in reraise
[Tue Mar 15 10:55:02.755262 2022] [wsgi:error] [pid 809976] [remote 46.28.73.122:31749]     raise new from exc
[Tue Mar 15 10:55:02.755276 2022] [wsgi:error] [pid 809976] [remote 46.28.73.122:31749] django.template.exceptions.TemplateDoesNotExist: blog/base.html 
[Tue Mar 15 10:55:02.983668 2022] [wsgi:error] [pid 809976] [remote 46.28.73.122:31750] Not Found: /favicon.ico
[Tue Mar 15 10:55:08.948860 2022] [wsgi:error] [pid 809976] [remote 46.28.73.122:31751] Internal Server Error: /category/test
[Tue Mar 15 10:55:08.948929 2022] [wsgi:error] [pid 809976] [remote 46.28.73.122:31751] Traceback (most recent call last):
[Tue Mar 15 10:55:08.948945 2022] [wsgi:error] [pid 809976] [remote 46.28.73.122:31751]   File "/django-project/venv/lib/python3.9/site-packages/django/template/backends/django.py", line 62, in render
[Tue Mar 15 10:55:08.948959 2022] [wsgi:error] [pid 809976] [remote 46.28.73.122:31751]     return self.template.render(context)
[Tue Mar 15 10:55:08.948973 2022] [wsgi:error] [pid 809976] [remote 46.28.73.122:31751]   File "/django-project/venv/lib/python3.9/site-packages/django/template/base.py", line 175, in render
[Tue Mar 15 10:55:08.948987 2022] [wsgi:error] [pid 809976] [remote 46.28.73.122:31751]     return self._render(context)
[Tue Mar 15 10:55:08.949001 2022] [wsgi:error] [pid 809976] [remote 46.28.73.122:31751]   File "/django-project/venv/lib/python3.9/site-packages/django/template/base.py", line 167, in _render
[Tue Mar 15 10:55:08.949015 2022] [wsgi:error] [pid 809976] [remote 46.28.73.122:31751]     return self.nodelist.render(context)
[Tue Mar 15 10:55:08.949029 2022] [wsgi:error] [pid 809976] [remote 46.28.73.122:31751]   File "/django-project/venv/lib/python3.9/site-packages/django/template/base.py", line 1000, in render
[Tue Mar 15 10:55:08.949043 2022] [wsgi:error] [pid 809976] [remote 46.28.73.122:31751]     return SafeString("".join([node.render_annotated(context) for node in self]))
[Tue Mar 15 10:55:08.949057 2022] [wsgi:error] [pid 809976] [remote 46.28.73.122:31751]   File "/django-project/venv/lib/python3.9/site-packages/django/template/base.py", line 1000, in <listcomp>
[Tue Mar 15 10:55:08.949071 2022] [wsgi:error] [pid 809976] [remote 46.28.73.122:31751]     return SafeString("".join([node.render_annotated(context) for node in self]))
[Tue Mar 15 10:55:08.949085 2022] [wsgi:error] [pid 809976] [remote 46.28.73.122:31751]   File "/django-project/venv/lib/python3.9/site-packages/django/template/base.py", line 958, in render_annotated
[Tue Mar 15 10:55:08.949099 2022] [wsgi:error] [pid 809976] [remote 46.28.73.122:31751]     return self.render(context)
[Tue Mar 15 10:55:08.949113 2022] [wsgi:error] [pid 809976] [remote 46.28.73.122:31751]   File "/django-project/venv/lib/python3.9/site-packages/django/template/loader_tags.py", line 132, in render
[Tue Mar 15 10:55:08.949127 2022] [wsgi:error] [pid 809976] [remote 46.28.73.122:31751]     compiled_parent = self.get_parent(context)
[Tue Mar 15 10:55:08.949141 2022] [wsgi:error] [pid 809976] [remote 46.28.73.122:31751]   File "/django-project/venv/lib/python3.9/site-packages/django/template/loader_tags.py", line 129, in get_parent
[Tue Mar 15 10:55:08.949155 2022] [wsgi:error] [pid 809976] [remote 46.28.73.122:31751]     return self.find_template(parent, context)
[Tue Mar 15 10:55:08.949168 2022] [wsgi:error] [pid 809976] [remote 46.28.73.122:31751]   File "/django-project/venv/lib/python3.9/site-packages/django/template/loader_tags.py", line 107, in find_template
[Tue Mar 15 10:55:08.949182 2022] [wsgi:error] [pid 809976] [remote 46.28.73.122:31751]     template, origin = context.template.engine.find_template(
[Tue Mar 15 10:55:08.949196 2022] [wsgi:error] [pid 809976] [remote 46.28.73.122:31751]   File "/django-project/venv/lib/python3.9/site-packages/django/template/engine.py", line 162, in find_template
[Tue Mar 15 10:55:08.949242 2022] [wsgi:error] [pid 809976] [remote 46.28.73.122:31751]     raise TemplateDoesNotExist(name, tried=tried)
[Tue Mar 15 10:55:08.949256 2022] [wsgi:error] [pid 809976] [remote 46.28.73.122:31751] django.template.exceptions.TemplateDoesNotExist: blog/base.html 
[Tue Mar 15 10:55:08.949270 2022] [wsgi:error] [pid 809976] [remote 46.28.73.122:31751] 
[Tue Mar 15 10:55:08.949283 2022] [wsgi:error] [pid 809976] [remote 46.28.73.122:31751] The above exception was the direct cause of the following exception:
[Tue Mar 15 10:55:08.949297 2022] [wsgi:error] [pid 809976] [remote 46.28.73.122:31751] 
[Tue Mar 15 10:55:08.949311 2022] [wsgi:error] [pid 809976] [remote 46.28.73.122:31751] Traceback (most recent call last):
[Tue Mar 15 10:55:08.949325 2022] [wsgi:error] [pid 809976] [remote 46.28.73.122:31751]   File "/django-project/venv/lib/python3.9/site-packages/django/core/handlers/exception.py", line 55, in inner
[Tue Mar 15 10:55:08.949339 2022] [wsgi:error] [pid 809976] [remote 46.28.73.122:31751]     response = get_response(request)
[Tue Mar 15 10:55:08.949353 2022] [wsgi:error] [pid 809976] [remote 46.28.73.122:31751]   File "/django-project/venv/lib/python3.9/site-packages/django/core/handlers/base.py", line 220, in _get_response
[Tue Mar 15 10:55:08.949367 2022] [wsgi:error] [pid 809976] [remote 46.28.73.122:31751]     response = response.render()
[Tue Mar 15 10:55:08.949380 2022] [wsgi:error] [pid 809976] [remote 46.28.73.122:31751]   File "/django-project/venv/lib/python3.9/site-packages/django/template/response.py", line 114, in render
[Tue Mar 15 10:55:08.949395 2022] [wsgi:error] [pid 809976] [remote 46.28.73.122:31751]     self.content = self.rendered_content
[Tue Mar 15 10:55:08.949408 2022] [wsgi:error] [pid 809976] [remote 46.28.73.122:31751]   File "/django-project/venv/lib/python3.9/site-packages/django/template/response.py", line 92, in rendered_content
[Tue Mar 15 10:55:08.949423 2022] [wsgi:error] [pid 809976] [remote 46.28.73.122:31751]     return template.render(context, self._request)
[Tue Mar 15 10:55:08.949436 2022] [wsgi:error] [pid 809976] [remote 46.28.73.122:31751]   File "/django-project/venv/lib/python3.9/site-packages/django/template/backends/django.py", line 64, in render
[Tue Mar 15 10:55:08.949451 2022] [wsgi:error] [pid 809976] [remote 46.28.73.122:31751]     reraise(exc, self.backend)
[Tue Mar 15 10:55:08.949464 2022] [wsgi:error] [pid 809976] [remote 46.28.73.122:31751]   File "/django-project/venv/lib/python3.9/site-packages/django/template/backends/django.py", line 85, in reraise
[Tue Mar 15 10:55:08.949478 2022] [wsgi:error] [pid 809976] [remote 46.28.73.122:31751]     raise new from exc
[Tue Mar 15 10:55:08.949492 2022] [wsgi:error] [pid 809976] [remote 46.28.73.122:31751] django.template.exceptions.TemplateDoesNotExist: blog/base.html 
[Tue Mar 15 10:56:26.845877 2022] [wsgi:error] [pid 809976] [remote 46.28.73.122:31776] Not Found: /favicon.ico
[Tue Mar 15 10:56:34.068484 2022] [wsgi:error] [pid 809976] [remote 46.28.73.122:31788] Not Found: /favicon.ico
[Tue Mar 15 10:57:38.398307 2022] [wsgi:error] [pid 809976] [remote 46.28.73.122:31804] Internal Server Error: /admin/blog/article/add/
[Tue Mar 15 10:57:38.398378 2022] [wsgi:error] [pid 809976] [remote 46.28.73.122:31804] Traceback (most recent call last):
[Tue Mar 15 10:57:38.398394 2022] [wsgi:error] [pid 809976] [remote 46.28.73.122:31804]   File "/django-project/venv/lib/python3.9/site-packages/django/core/handlers/exception.py", line 55, in inner
[Tue Mar 15 10:57:38.398408 2022] [wsgi:error] [pid 809976] [remote 46.28.73.122:31804]     response = get_response(request)
[Tue Mar 15 10:57:38.398423 2022] [wsgi:error] [pid 809976] [remote 46.28.73.122:31804]   File "/django-project/venv/lib/python3.9/site-packages/django/core/handlers/base.py", line 197, in _get_response
[Tue Mar 15 10:57:38.398437 2022] [wsgi:error] [pid 809976] [remote 46.28.73.122:31804]     response = wrapped_callback(request, *callback_args, **callback_kwargs)
[Tue Mar 15 10:57:38.398473 2022] [wsgi:error] [pid 809976] [remote 46.28.73.122:31804]   File "/django-project/venv/lib/python3.9/site-packages/django/contrib/admin/options.py", line 683, in wrapper
[Tue Mar 15 10:57:38.398487 2022] [wsgi:error] [pid 809976] [remote 46.28.73.122:31804]     return self.admin_site.admin_view(view)(*args, **kwargs)
[Tue Mar 15 10:57:38.398501 2022] [wsgi:error] [pid 809976] [remote 46.28.73.122:31804]   File "/django-project/venv/lib/python3.9/site-packages/django/utils/decorators.py", line 133, in _wrapped_view
[Tue Mar 15 10:57:38.398516 2022] [wsgi:error] [pid 809976] [remote 46.28.73.122:31804]     response = view_func(request, *args, **kwargs)
[Tue Mar 15 10:57:38.398529 2022] [wsgi:error] [pid 809976] [remote 46.28.73.122:31804]   File "/django-project/venv/lib/python3.9/site-packages/django/views/decorators/cache.py", line 62, in _wrapped_view_func
[Tue Mar 15 10:57:38.398544 2022] [wsgi:error] [pid 809976] [remote 46.28.73.122:31804]     response = view_func(request, *args, **kwargs)
[Tue Mar 15 10:57:38.398558 2022] [wsgi:error] [pid 809976] [remote 46.28.73.122:31804]   File "/django-project/venv/lib/python3.9/site-packages/django/contrib/admin/sites.py", line 242, in inner
[Tue Mar 15 10:57:38.398572 2022] [wsgi:error] [pid 809976] [remote 46.28.73.122:31804]     return view(request, *args, **kwargs)
[Tue Mar 15 10:57:38.398586 2022] [wsgi:error] [pid 809976] [remote 46.28.73.122:31804]   File "/django-project/venv/lib/python3.9/site-packages/django/contrib/admin/options.py", line 1885, in add_view
[Tue Mar 15 10:57:38.398600 2022] [wsgi:error] [pid 809976] [remote 46.28.73.122:31804]     return self.changeform_view(request, None, form_url, extra_context)
[Tue Mar 15 10:57:38.398634 2022] [wsgi:error] [pid 809976] [remote 46.28.73.122:31804]   File "/django-project/venv/lib/python3.9/site-packages/django/utils/decorators.py", line 46, in _wrapper
[Tue Mar 15 10:57:38.398651 2022] [wsgi:error] [pid 809976] [remote 46.28.73.122:31804]     return bound_method(*args, **kwargs)
[Tue Mar 15 10:57:38.398665 2022] [wsgi:error] [pid 809976] [remote 46.28.73.122:31804]   File "/django-project/venv/lib/python3.9/site-packages/django/utils/decorators.py", line 133, in _wrapped_view
[Tue Mar 15 10:57:38.398679 2022] [wsgi:error] [pid 809976] [remote 46.28.73.122:31804]     response = view_func(request, *args, **kwargs)
[Tue Mar 15 10:57:38.398693 2022] [wsgi:error] [pid 809976] [remote 46.28.73.122:31804]   File "/django-project/venv/lib/python3.9/site-packages/django/contrib/admin/options.py", line 1745, in changeform_view
[Tue Mar 15 10:57:38.398707 2022] [wsgi:error] [pid 809976] [remote 46.28.73.122:31804]     return self._changeform_view(request, object_id, form_url, extra_context)
[Tue Mar 15 10:57:38.398721 2022] [wsgi:error] [pid 809976] [remote 46.28.73.122:31804]   File "/django-project/venv/lib/python3.9/site-packages/django/contrib/admin/options.py", line 1797, in _changeform_view
[Tue Mar 15 10:57:38.398735 2022] [wsgi:error] [pid 809976] [remote 46.28.73.122:31804]     self.save_model(request, new_object, form, not add)
[Tue Mar 15 10:57:38.398749 2022] [wsgi:error] [pid 809976] [remote 46.28.73.122:31804]   File "/django-project/venv/lib/python3.9/site-packages/django/contrib/admin/options.py", line 1220, in save_model
[Tue Mar 15 10:57:38.398763 2022] [wsgi:error] [pid 809976] [remote 46.28.73.122:31804]     obj.save()
[Tue Mar 15 10:57:38.398777 2022] [wsgi:error] [pid 809976] [remote 46.28.73.122:31804]   File "/django-project/venv/lib/python3.9/site-packages/django/db/models/base.py", line 806, in save
[Tue Mar 15 10:57:38.398791 2022] [wsgi:error] [pid 809976] [remote 46.28.73.122:31804]     self.save_base(
[Tue Mar 15 10:57:38.398805 2022] [wsgi:error] [pid 809976] [remote 46.28.73.122:31804]   File "/django-project/venv/lib/python3.9/site-packages/django/db/models/base.py", line 857, in save_base
[Tue Mar 15 10:57:38.398819 2022] [wsgi:error] [pid 809976] [remote 46.28.73.122:31804]     updated = self._save_table(
[Tue Mar 15 10:57:38.398833 2022] [wsgi:error] [pid 809976] [remote 46.28.73.122:31804]   File "/django-project/venv/lib/python3.9/site-packages/django/db/models/base.py", line 1000, in _save_table
[Tue Mar 15 10:57:38.398861 2022] [wsgi:error] [pid 809976] [remote 46.28.73.122:31804]     results = self._do_insert(
[Tue Mar 15 10:57:38.398875 2022] [wsgi:error] [pid 809976] [remote 46.28.73.122:31804]   File "/django-project/venv/lib/python3.9/site-packages/django/db/models/base.py", line 1041, in _do_insert
[Tue Mar 15 10:57:38.398889 2022] [wsgi:error] [pid 809976] [remote 46.28.73.122:31804]     return manager._insert(
[Tue Mar 15 10:57:38.398903 2022] [wsgi:error] [pid 809976] [remote 46.28.73.122:31804]   File "/django-project/venv/lib/python3.9/site-packages/django/db/models/manager.py", line 85, in manager_method
[Tue Mar 15 10:57:38.398917 2022] [wsgi:error] [pid 809976] [remote 46.28.73.122:31804]     return getattr(self.get_queryset(), name)(*args, **kwargs)
[Tue Mar 15 10:57:38.398931 2022] [wsgi:error] [pid 809976] [remote 46.28.73.122:31804]   File "/django-project/venv/lib/python3.9/site-packages/django/db/models/query.py", line 1434, in _insert
[Tue Mar 15 10:57:38.398946 2022] [wsgi:error] [pid 809976] [remote 46.28.73.122:31804]     return query.get_compiler(using=using).execute_sql(returning_fields)
[Tue Mar 15 10:57:38.398960 2022] [wsgi:error] [pid 809976] [remote 46.28.73.122:31804]   File "/django-project/venv/lib/python3.9/site-packages/django/db/models/sql/compiler.py", line 1620, in execute_sql
[Tue Mar 15 10:57:38.398974 2022] [wsgi:error] [pid 809976] [remote 46.28.73.122:31804]     for sql, params in self.as_sql():
[Tue Mar 15 10:57:38.398988 2022] [wsgi:error] [pid 809976] [remote 46.28.73.122:31804]   File "/django-project/venv/lib/python3.9/site-packages/django/db/models/sql/compiler.py", line 1547, in as_sql
[Tue Mar 15 10:57:38.399002 2022] [wsgi:error] [pid 809976] [remote 46.28.73.122:31804]     value_rows = [
[Tue Mar 15 10:57:38.399016 2022] [wsgi:error] [pid 809976] [remote 46.28.73.122:31804]   File "/django-project/venv/lib/python3.9/site-packages/django/db/models/sql/compiler.py", line 1548, in <listcomp>
[Tue Mar 15 10:57:38.399030 2022] [wsgi:error] [pid 809976] [remote 46.28.73.122:31804]     [
[Tue Mar 15 10:57:38.399044 2022] [wsgi:error] [pid 809976] [remote 46.28.73.122:31804]   File "/django-project/venv/lib/python3.9/site-packages/django/db/models/sql/compiler.py", line 1549, in <listcomp>
[Tue Mar 15 10:57:38.399058 2022] [wsgi:error] [pid 809976] [remote 46.28.73.122:31804]     self.prepare_value(field, self.pre_save_val(field, obj))
[Tue Mar 15 10:57:38.399072 2022] [wsgi:error] [pid 809976] [remote 46.28.73.122:31804]   File "/django-project/venv/lib/python3.9/site-packages/django/db/models/sql/compiler.py", line 1497, in pre_save_val
[Tue Mar 15 10:57:38.399086 2022] [wsgi:error] [pid 809976] [remote 46.28.73.122:31804]     return field.pre_save(obj, add=True)
[Tue Mar 15 10:57:38.399100 2022] [wsgi:error] [pid 809976] [remote 46.28.73.122:31804]   File "/django-project/venv/lib/python3.9/site-packages/django/db/models/fields/files.py", line 316, in pre_save
[Tue Mar 15 10:57:38.399114 2022] [wsgi:error] [pid 809976] [remote 46.28.73.122:31804]     file.save(file.name, file.file, save=False)
[Tue Mar 15 10:57:38.399128 2022] [wsgi:error] [pid 809976] [remote 46.28.73.122:31804]   File "/django-project/venv/lib/python3.9/site-packages/django/db/models/fields/files.py", line 92, in save
[Tue Mar 15 10:57:38.399142 2022] [wsgi:error] [pid 809976] [remote 46.28.73.122:31804]     self.name = self.storage.save(name, content, max_length=self.field.max_length)
[Tue Mar 15 10:57:38.399157 2022] [wsgi:error] [pid 809976] [remote 46.28.73.122:31804]   File "/django-project/venv/lib/python3.9/site-packages/django/core/files/storage.py", line 57, in save
[Tue Mar 15 10:57:38.399171 2022] [wsgi:error] [pid 809976] [remote 46.28.73.122:31804]     name = self._save(name, content)
[Tue Mar 15 10:57:38.399185 2022] [wsgi:error] [pid 809976] [remote 46.28.73.122:31804]   File "/django-project/venv/lib/python3.9/site-packages/django/core/files/storage.py", line 296, in _save
[Tue Mar 15 10:57:38.399211 2022] [wsgi:error] [pid 809976] [remote 46.28.73.122:31804]     os.makedirs(directory, exist_ok=True)
[Tue Mar 15 10:57:38.399225 2022] [wsgi:error] [pid 809976] [remote 46.28.73.122:31804]   File "/usr/lib/python3.9/os.py", line 225, in makedirs
[Tue Mar 15 10:57:38.399239 2022] [wsgi:error] [pid 809976] [remote 46.28.73.122:31804]     mkdir(name, mode)
[Tue Mar 15 10:57:38.399253 2022] [wsgi:error] [pid 809976] [remote 46.28.73.122:31804] PermissionError: [Errno 13] Permission denied: '/django-project/hopenetwork/site/public/media/images'
[Tue Mar 15 10:57:38.908098 2022] [wsgi:error] [pid 809976] [remote 46.28.73.122:31805] Not Found: /favicon.ico
[Tue Mar 15 10:58:30.708457 2022] [wsgi:error] [pid 809976] [remote 46.28.73.122:31813] Not Found: /favicon.ico
[Tue Mar 15 10:58:37.361196 2022] [wsgi:error] [pid 809976] [remote 46.28.73.122:31819] Not Found: /assets/favicon.ico
[Tue Mar 15 10:58:39.193511 2022] [wsgi:error] [pid 809976] [remote 46.28.73.122:31822] Internal Server Error: /category/cisco
[Tue Mar 15 10:58:39.193579 2022] [wsgi:error] [pid 809976] [remote 46.28.73.122:31822] Traceback (most recent call last):
[Tue Mar 15 10:58:39.193595 2022] [wsgi:error] [pid 809976] [remote 46.28.73.122:31822]   File "/django-project/venv/lib/python3.9/site-packages/django/template/backends/django.py", line 62, in render
[Tue Mar 15 10:58:39.193610 2022] [wsgi:error] [pid 809976] [remote 46.28.73.122:31822]     return self.template.render(context)
[Tue Mar 15 10:58:39.193625 2022] [wsgi:error] [pid 809976] [remote 46.28.73.122:31822]   File "/django-project/venv/lib/python3.9/site-packages/django/template/base.py", line 175, in render
[Tue Mar 15 10:58:39.193639 2022] [wsgi:error] [pid 809976] [remote 46.28.73.122:31822]     return self._render(context)
[Tue Mar 15 10:58:39.193653 2022] [wsgi:error] [pid 809976] [remote 46.28.73.122:31822]   File "/django-project/venv/lib/python3.9/site-packages/django/template/base.py", line 167, in _render
[Tue Mar 15 10:58:39.193667 2022] [wsgi:error] [pid 809976] [remote 46.28.73.122:31822]     return self.nodelist.render(context)
[Tue Mar 15 10:58:39.193681 2022] [wsgi:error] [pid 809976] [remote 46.28.73.122:31822]   File "/django-project/venv/lib/python3.9/site-packages/django/template/base.py", line 1000, in render
[Tue Mar 15 10:58:39.193696 2022] [wsgi:error] [pid 809976] [remote 46.28.73.122:31822]     return SafeString("".join([node.render_annotated(context) for node in self]))
[Tue Mar 15 10:58:39.193710 2022] [wsgi:error] [pid 809976] [remote 46.28.73.122:31822]   File "/django-project/venv/lib/python3.9/site-packages/django/template/base.py", line 1000, in <listcomp>
[Tue Mar 15 10:58:39.193725 2022] [wsgi:error] [pid 809976] [remote 46.28.73.122:31822]     return SafeString("".join([node.render_annotated(context) for node in self]))
[Tue Mar 15 10:58:39.193739 2022] [wsgi:error] [pid 809976] [remote 46.28.73.122:31822]   File "/django-project/venv/lib/python3.9/site-packages/django/template/base.py", line 958, in render_annotated
[Tue Mar 15 10:58:39.193753 2022] [wsgi:error] [pid 809976] [remote 46.28.73.122:31822]     return self.render(context)
[Tue Mar 15 10:58:39.193767 2022] [wsgi:error] [pid 809976] [remote 46.28.73.122:31822]   File "/django-project/venv/lib/python3.9/site-packages/django/template/loader_tags.py", line 132, in render
[Tue Mar 15 10:58:39.193782 2022] [wsgi:error] [pid 809976] [remote 46.28.73.122:31822]     compiled_parent = self.get_parent(context)
[Tue Mar 15 10:58:39.193796 2022] [wsgi:error] [pid 809976] [remote 46.28.73.122:31822]   File "/django-project/venv/lib/python3.9/site-packages/django/template/loader_tags.py", line 129, in get_parent
[Tue Mar 15 10:58:39.193810 2022] [wsgi:error] [pid 809976] [remote 46.28.73.122:31822]     return self.find_template(parent, context)
[Tue Mar 15 10:58:39.193824 2022] [wsgi:error] [pid 809976] [remote 46.28.73.122:31822]   File "/django-project/venv/lib/python3.9/site-packages/django/template/loader_tags.py", line 107, in find_template
[Tue Mar 15 10:58:39.193868 2022] [wsgi:error] [pid 809976] [remote 46.28.73.122:31822]     template, origin = context.template.engine.find_template(
[Tue Mar 15 10:58:39.193883 2022] [wsgi:error] [pid 809976] [remote 46.28.73.122:31822]   File "/django-project/venv/lib/python3.9/site-packages/django/template/engine.py", line 162, in find_template
[Tue Mar 15 10:58:39.193897 2022] [wsgi:error] [pid 809976] [remote 46.28.73.122:31822]     raise TemplateDoesNotExist(name, tried=tried)
[Tue Mar 15 10:58:39.193911 2022] [wsgi:error] [pid 809976] [remote 46.28.73.122:31822] django.template.exceptions.TemplateDoesNotExist: blog/base.html 
[Tue Mar 15 10:58:39.193925 2022] [wsgi:error] [pid 809976] [remote 46.28.73.122:31822] 
[Tue Mar 15 10:58:39.193939 2022] [wsgi:error] [pid 809976] [remote 46.28.73.122:31822] The above exception was the direct cause of the following exception:
[Tue Mar 15 10:58:39.193953 2022] [wsgi:error] [pid 809976] [remote 46.28.73.122:31822] 
[Tue Mar 15 10:58:39.193967 2022] [wsgi:error] [pid 809976] [remote 46.28.73.122:31822] Traceback (most recent call last):
[Tue Mar 15 10:58:39.193981 2022] [wsgi:error] [pid 809976] [remote 46.28.73.122:31822]   File "/django-project/venv/lib/python3.9/site-packages/django/core/handlers/exception.py", line 55, in inner
[Tue Mar 15 10:58:39.193995 2022] [wsgi:error] [pid 809976] [remote 46.28.73.122:31822]     response = get_response(request)
[Tue Mar 15 10:58:39.194009 2022] [wsgi:error] [pid 809976] [remote 46.28.73.122:31822]   File "/django-project/venv/lib/python3.9/site-packages/django/core/handlers/base.py", line 220, in _get_response
[Tue Mar 15 10:58:39.194024 2022] [wsgi:error] [pid 809976] [remote 46.28.73.122:31822]     response = response.render()
[Tue Mar 15 10:58:39.194038 2022] [wsgi:error] [pid 809976] [remote 46.28.73.122:31822]   File "/django-project/venv/lib/python3.9/site-packages/django/template/response.py", line 114, in render
[Tue Mar 15 10:58:39.194052 2022] [wsgi:error] [pid 809976] [remote 46.28.73.122:31822]     self.content = self.rendered_content
[Tue Mar 15 10:58:39.194066 2022] [wsgi:error] [pid 809976] [remote 46.28.73.122:31822]   File "/django-project/venv/lib/python3.9/site-packages/django/template/response.py", line 92, in rendered_content
[Tue Mar 15 10:58:39.194080 2022] [wsgi:error] [pid 809976] [remote 46.28.73.122:31822]     return template.render(context, self._request)
[Tue Mar 15 10:58:39.194095 2022] [wsgi:error] [pid 809976] [remote 46.28.73.122:31822]   File "/django-project/venv/lib/python3.9/site-packages/django/template/backends/django.py", line 64, in render
[Tue Mar 15 10:58:39.194109 2022] [wsgi:error] [pid 809976] [remote 46.28.73.122:31822]     reraise(exc, self.backend)
[Tue Mar 15 10:58:39.194123 2022] [wsgi:error] [pid 809976] [remote 46.28.73.122:31822]   File "/django-project/venv/lib/python3.9/site-packages/django/template/backends/django.py", line 85, in reraise
[Tue Mar 15 10:58:39.194137 2022] [wsgi:error] [pid 809976] [remote 46.28.73.122:31822]     raise new from exc
[Tue Mar 15 10:58:39.194151 2022] [wsgi:error] [pid 809976] [remote 46.28.73.122:31822] django.template.exceptions.TemplateDoesNotExist: blog/base.html 
[Tue Mar 15 10:58:43.575853 2022] [wsgi:error] [pid 809976] [remote 46.28.73.122:31823] Internal Server Error: /category/mikrotik
[Tue Mar 15 10:58:43.575923 2022] [wsgi:error] [pid 809976] [remote 46.28.73.122:31823] Traceback (most recent call last):
[Tue Mar 15 10:58:43.575945 2022] [wsgi:error] [pid 809976] [remote 46.28.73.122:31823]   File "/django-project/venv/lib/python3.9/site-packages/django/template/backends/django.py", line 62, in render
[Tue Mar 15 10:58:43.575964 2022] [wsgi:error] [pid 809976] [remote 46.28.73.122:31823]     return self.template.render(context)
[Tue Mar 15 10:58:43.575984 2022] [wsgi:error] [pid 809976] [remote 46.28.73.122:31823]   File "/django-project/venv/lib/python3.9/site-packages/django/template/base.py", line 175, in render
[Tue Mar 15 10:58:43.576002 2022] [wsgi:error] [pid 809976] [remote 46.28.73.122:31823]     return self._render(context)
[Tue Mar 15 10:58:43.576050 2022] [wsgi:error] [pid 809976] [remote 46.28.73.122:31823]   File "/django-project/venv/lib/python3.9/site-packages/django/template/base.py", line 167, in _render
[Tue Mar 15 10:58:43.576070 2022] [wsgi:error] [pid 809976] [remote 46.28.73.122:31823]     return self.nodelist.render(context)
[Tue Mar 15 10:58:43.576089 2022] [wsgi:error] [pid 809976] [remote 46.28.73.122:31823]   File "/django-project/venv/lib/python3.9/site-packages/django/template/base.py", line 1000, in render
[Tue Mar 15 10:58:43.576108 2022] [wsgi:error] [pid 809976] [remote 46.28.73.122:31823]     return SafeString("".join([node.render_annotated(context) for node in self]))
[Tue Mar 15 10:58:43.576127 2022] [wsgi:error] [pid 809976] [remote 46.28.73.122:31823]   File "/django-project/venv/lib/python3.9/site-packages/django/template/base.py", line 1000, in <listcomp>
[Tue Mar 15 10:58:43.576146 2022] [wsgi:error] [pid 809976] [remote 46.28.73.122:31823]     return SafeString("".join([node.render_annotated(context) for node in self]))
[Tue Mar 15 10:58:43.576165 2022] [wsgi:error] [pid 809976] [remote 46.28.73.122:31823]   File "/django-project/venv/lib/python3.9/site-packages/django/template/base.py", line 958, in render_annotated
[Tue Mar 15 10:58:43.576184 2022] [wsgi:error] [pid 809976] [remote 46.28.73.122:31823]     return self.render(context)
[Tue Mar 15 10:58:43.576203 2022] [wsgi:error] [pid 809976] [remote 46.28.73.122:31823]   File "/django-project/venv/lib/python3.9/site-packages/django/template/loader_tags.py", line 132, in render
[Tue Mar 15 10:58:43.576222 2022] [wsgi:error] [pid 809976] [remote 46.28.73.122:31823]     compiled_parent = self.get_parent(context)
[Tue Mar 15 10:58:43.576241 2022] [wsgi:error] [pid 809976] [remote 46.28.73.122:31823]   File "/django-project/venv/lib/python3.9/site-packages/django/template/loader_tags.py", line 129, in get_parent
[Tue Mar 15 10:58:43.576260 2022] [wsgi:error] [pid 809976] [remote 46.28.73.122:31823]     return self.find_template(parent, context)
[Tue Mar 15 10:58:43.576278 2022] [wsgi:error] [pid 809976] [remote 46.28.73.122:31823]   File "/django-project/venv/lib/python3.9/site-packages/django/template/loader_tags.py", line 107, in find_template
[Tue Mar 15 10:58:43.576298 2022] [wsgi:error] [pid 809976] [remote 46.28.73.122:31823]     template, origin = context.template.engine.find_template(
[Tue Mar 15 10:58:43.576316 2022] [wsgi:error] [pid 809976] [remote 46.28.73.122:31823]   File "/django-project/venv/lib/python3.9/site-packages/django/template/engine.py", line 162, in find_template
[Tue Mar 15 10:58:43.576335 2022] [wsgi:error] [pid 809976] [remote 46.28.73.122:31823]     raise TemplateDoesNotExist(name, tried=tried)
[Tue Mar 15 10:58:43.576354 2022] [wsgi:error] [pid 809976] [remote 46.28.73.122:31823] django.template.exceptions.TemplateDoesNotExist: blog/base.html 
[Tue Mar 15 10:58:43.576373 2022] [wsgi:error] [pid 809976] [remote 46.28.73.122:31823] 
[Tue Mar 15 10:58:43.576391 2022] [wsgi:error] [pid 809976] [remote 46.28.73.122:31823] The above exception was the direct cause of the following exception:
[Tue Mar 15 10:58:43.576409 2022] [wsgi:error] [pid 809976] [remote 46.28.73.122:31823] 
[Tue Mar 15 10:58:43.576428 2022] [wsgi:error] [pid 809976] [remote 46.28.73.122:31823] Traceback (most recent call last):
[Tue Mar 15 10:58:43.576446 2022] [wsgi:error] [pid 809976] [remote 46.28.73.122:31823]   File "/django-project/venv/lib/python3.9/site-packages/django/core/handlers/exception.py", line 55, in inner
[Tue Mar 15 10:58:43.576466 2022] [wsgi:error] [pid 809976] [remote 46.28.73.122:31823]     response = get_response(request)
[Tue Mar 15 10:58:43.576484 2022] [wsgi:error] [pid 809976] [remote 46.28.73.122:31823]   File "/django-project/venv/lib/python3.9/site-packages/django/core/handlers/base.py", line 220, in _get_response
[Tue Mar 15 10:58:43.576503 2022] [wsgi:error] [pid 809976] [remote 46.28.73.122:31823]     response = response.render()
[Tue Mar 15 10:58:43.576522 2022] [wsgi:error] [pid 809976] [remote 46.28.73.122:31823]   File "/django-project/venv/lib/python3.9/site-packages/django/template/response.py", line 114, in render
[Tue Mar 15 10:58:43.576558 2022] [wsgi:error] [pid 809976] [remote 46.28.73.122:31823]     self.content = self.rendered_content
[Tue Mar 15 10:58:43.576577 2022] [wsgi:error] [pid 809976] [remote 46.28.73.122:31823]   File "/django-project/venv/lib/python3.9/site-packages/django/template/response.py", line 92, in rendered_content
[Tue Mar 15 10:58:43.576596 2022] [wsgi:error] [pid 809976] [remote 46.28.73.122:31823]     return template.render(context, self._request)
[Tue Mar 15 10:58:43.576615 2022] [wsgi:error] [pid 809976] [remote 46.28.73.122:31823]   File "/django-project/venv/lib/python3.9/site-packages/django/template/backends/django.py", line 64, in render
[Tue Mar 15 10:58:43.576634 2022] [wsgi:error] [pid 809976] [remote 46.28.73.122:31823]     reraise(exc, self.backend)
[Tue Mar 15 10:58:43.576653 2022] [wsgi:error] [pid 809976] [remote 46.28.73.122:31823]   File "/django-project/venv/lib/python3.9/site-packages/django/template/backends/django.py", line 85, in reraise
[Tue Mar 15 10:58:43.576672 2022] [wsgi:error] [pid 809976] [remote 46.28.73.122:31823]     raise new from exc
[Tue Mar 15 10:58:43.576691 2022] [wsgi:error] [pid 809976] [remote 46.28.73.122:31823] django.template.exceptions.TemplateDoesNotExist: blog/base.html 
[Tue Mar 15 10:58:50.649375 2022] [wsgi:error] [pid 809976] [remote 46.28.73.122:31831] Internal Server Error: /category/Network
[Tue Mar 15 10:58:50.649441 2022] [wsgi:error] [pid 809976] [remote 46.28.73.122:31831] Traceback (most recent call last):
[Tue Mar 15 10:58:50.649456 2022] [wsgi:error] [pid 809976] [remote 46.28.73.122:31831]   File "/django-project/venv/lib/python3.9/site-packages/django/template/backends/django.py", line 62, in render
[Tue Mar 15 10:58:50.649471 2022] [wsgi:error] [pid 809976] [remote 46.28.73.122:31831]     return self.template.render(context)
[Tue Mar 15 10:58:50.649485 2022] [wsgi:error] [pid 809976] [remote 46.28.73.122:31831]   File "/django-project/venv/lib/python3.9/site-packages/django/template/base.py", line 175, in render
[Tue Mar 15 10:58:50.649500 2022] [wsgi:error] [pid 809976] [remote 46.28.73.122:31831]     return self._render(context)
[Tue Mar 15 10:58:50.649514 2022] [wsgi:error] [pid 809976] [remote 46.28.73.122:31831]   File "/django-project/venv/lib/python3.9/site-packages/django/template/base.py", line 167, in _render
[Tue Mar 15 10:58:50.649528 2022] [wsgi:error] [pid 809976] [remote 46.28.73.122:31831]     return self.nodelist.render(context)
[Tue Mar 15 10:58:50.649542 2022] [wsgi:error] [pid 809976] [remote 46.28.73.122:31831]   File "/django-project/venv/lib/python3.9/site-packages/django/template/base.py", line 1000, in render
[Tue Mar 15 10:58:50.649557 2022] [wsgi:error] [pid 809976] [remote 46.28.73.122:31831]     return SafeString("".join([node.render_annotated(context) for node in self]))
[Tue Mar 15 10:58:50.649571 2022] [wsgi:error] [pid 809976] [remote 46.28.73.122:31831]   File "/django-project/venv/lib/python3.9/site-packages/django/template/base.py", line 1000, in <listcomp>
[Tue Mar 15 10:58:50.649586 2022] [wsgi:error] [pid 809976] [remote 46.28.73.122:31831]     return SafeString("".join([node.render_annotated(context) for node in self]))
[Tue Mar 15 10:58:50.649600 2022] [wsgi:error] [pid 809976] [remote 46.28.73.122:31831]   File "/django-project/venv/lib/python3.9/site-packages/django/template/base.py", line 958, in render_annotated
[Tue Mar 15 10:58:50.649614 2022] [wsgi:error] [pid 809976] [remote 46.28.73.122:31831]     return self.render(context)
[Tue Mar 15 10:58:50.649629 2022] [wsgi:error] [pid 809976] [remote 46.28.73.122:31831]   File "/django-project/venv/lib/python3.9/site-packages/django/template/loader_tags.py", line 132, in render
[Tue Mar 15 10:58:50.649643 2022] [wsgi:error] [pid 809976] [remote 46.28.73.122:31831]     compiled_parent = self.get_parent(context)
[Tue Mar 15 10:58:50.649657 2022] [wsgi:error] [pid 809976] [remote 46.28.73.122:31831]   File "/django-project/venv/lib/python3.9/site-packages/django/template/loader_tags.py", line 129, in get_parent
[Tue Mar 15 10:58:50.649703 2022] [wsgi:error] [pid 809976] [remote 46.28.73.122:31831]     return self.find_template(parent, context)
[Tue Mar 15 10:58:50.649718 2022] [wsgi:error] [pid 809976] [remote 46.28.73.122:31831]   File "/django-project/venv/lib/python3.9/site-packages/django/template/loader_tags.py", line 107, in find_template
[Tue Mar 15 10:58:50.649732 2022] [wsgi:error] [pid 809976] [remote 46.28.73.122:31831]     template, origin = context.template.engine.find_template(
[Tue Mar 15 10:58:50.649746 2022] [wsgi:error] [pid 809976] [remote 46.28.73.122:31831]   File "/django-project/venv/lib/python3.9/site-packages/django/template/engine.py", line 162, in find_template
[Tue Mar 15 10:58:50.649761 2022] [wsgi:error] [pid 809976] [remote 46.28.73.122:31831]     raise TemplateDoesNotExist(name, tried=tried)
[Tue Mar 15 10:58:50.649775 2022] [wsgi:error] [pid 809976] [remote 46.28.73.122:31831] django.template.exceptions.TemplateDoesNotExist: blog/base.html 
[Tue Mar 15 10:58:50.649789 2022] [wsgi:error] [pid 809976] [remote 46.28.73.122:31831] 
[Tue Mar 15 10:58:50.649803 2022] [wsgi:error] [pid 809976] [remote 46.28.73.122:31831] The above exception was the direct cause of the following exception:
[Tue Mar 15 10:58:50.649817 2022] [wsgi:error] [pid 809976] [remote 46.28.73.122:31831] 
[Tue Mar 15 10:58:50.649830 2022] [wsgi:error] [pid 809976] [remote 46.28.73.122:31831] Traceback (most recent call last):
[Tue Mar 15 10:58:50.649845 2022] [wsgi:error] [pid 809976] [remote 46.28.73.122:31831]   File "/django-project/venv/lib/python3.9/site-packages/django/core/handlers/exception.py", line 55, in inner
[Tue Mar 15 10:58:50.649859 2022] [wsgi:error] [pid 809976] [remote 46.28.73.122:31831]     response = get_response(request)
[Tue Mar 15 10:58:50.649873 2022] [wsgi:error] [pid 809976] [remote 46.28.73.122:31831]   File "/django-project/venv/lib/python3.9/site-packages/django/core/handlers/base.py", line 220, in _get_response
[Tue Mar 15 10:58:50.649887 2022] [wsgi:error] [pid 809976] [remote 46.28.73.122:31831]     response = response.render()
[Tue Mar 15 10:58:50.649901 2022] [wsgi:error] [pid 809976] [remote 46.28.73.122:31831]   File "/django-project/venv/lib/python3.9/site-packages/django/template/response.py", line 114, in render
[Tue Mar 15 10:58:50.649916 2022] [wsgi:error] [pid 809976] [remote 46.28.73.122:31831]     self.content = self.rendered_content
[Tue Mar 15 10:58:50.649930 2022] [wsgi:error] [pid 809976] [remote 46.28.73.122:31831]   File "/django-project/venv/lib/python3.9/site-packages/django/template/response.py", line 92, in rendered_content
[Tue Mar 15 10:58:50.649944 2022] [wsgi:error] [pid 809976] [remote 46.28.73.122:31831]     return template.render(context, self._request)
[Tue Mar 15 10:58:50.649958 2022] [wsgi:error] [pid 809976] [remote 46.28.73.122:31831]   File "/django-project/venv/lib/python3.9/site-packages/django/template/backends/django.py", line 64, in render
[Tue Mar 15 10:58:50.649972 2022] [wsgi:error] [pid 809976] [remote 46.28.73.122:31831]     reraise(exc, self.backend)
[Tue Mar 15 10:58:50.649986 2022] [wsgi:error] [pid 809976] [remote 46.28.73.122:31831]   File "/django-project/venv/lib/python3.9/site-packages/django/template/backends/django.py", line 85, in reraise
[Tue Mar 15 10:58:50.650001 2022] [wsgi:error] [pid 809976] [remote 46.28.73.122:31831]     raise new from exc
[Tue Mar 15 10:58:50.650014 2022] [wsgi:error] [pid 809976] [remote 46.28.73.122:31831] django.template.exceptions.TemplateDoesNotExist: blog/base.html 
[Tue Mar 15 11:03:38.729435 2022] [wsgi:error] [pid 809976] [remote 46.28.73.122:31900] Not Found: /favicon.ico
[Tue Mar 15 11:03:54.946602 2022] [wsgi:error] [pid 809976] [remote 46.28.73.122:31919] Not Found: /assets/favicon.ico
[Tue Mar 15 11:04:00.800118 2022] [wsgi:error] [pid 809976] [remote 46.28.73.122:31922] Not Found: /assets/favicon.ico
[Tue Mar 15 11:04:10.192197 2022] [wsgi:error] [pid 809976] [remote 46.28.73.122:31930] Internal Server Error: /category/Network
[Tue Mar 15 11:04:10.192291 2022] [wsgi:error] [pid 809976] [remote 46.28.73.122:31930] Traceback (most recent call last):
[Tue Mar 15 11:04:10.192306 2022] [wsgi:error] [pid 809976] [remote 46.28.73.122:31930]   File "/django-project/venv/lib/python3.9/site-packages/django/template/backends/django.py", line 62, in render
[Tue Mar 15 11:04:10.192321 2022] [wsgi:error] [pid 809976] [remote 46.28.73.122:31930]     return self.template.render(context)
[Tue Mar 15 11:04:10.192335 2022] [wsgi:error] [pid 809976] [remote 46.28.73.122:31930]   File "/django-project/venv/lib/python3.9/site-packages/django/template/base.py", line 175, in render
[Tue Mar 15 11:04:10.192350 2022] [wsgi:error] [pid 809976] [remote 46.28.73.122:31930]     return self._render(context)
[Tue Mar 15 11:04:10.192364 2022] [wsgi:error] [pid 809976] [remote 46.28.73.122:31930]   File "/django-project/venv/lib/python3.9/site-packages/django/template/base.py", line 167, in _render
[Tue Mar 15 11:04:10.192378 2022] [wsgi:error] [pid 809976] [remote 46.28.73.122:31930]     return self.nodelist.render(context)
[Tue Mar 15 11:04:10.192392 2022] [wsgi:error] [pid 809976] [remote 46.28.73.122:31930]   File "/django-project/venv/lib/python3.9/site-packages/django/template/base.py", line 1000, in render
[Tue Mar 15 11:04:10.192407 2022] [wsgi:error] [pid 809976] [remote 46.28.73.122:31930]     return SafeString("".join([node.render_annotated(context) for node in self]))
[Tue Mar 15 11:04:10.192421 2022] [wsgi:error] [pid 809976] [remote 46.28.73.122:31930]   File "/django-project/venv/lib/python3.9/site-packages/django/template/base.py", line 1000, in <listcomp>
[Tue Mar 15 11:04:10.192435 2022] [wsgi:error] [pid 809976] [remote 46.28.73.122:31930]     return SafeString("".join([node.render_annotated(context) for node in self]))
[Tue Mar 15 11:04:10.192450 2022] [wsgi:error] [pid 809976] [remote 46.28.73.122:31930]   File "/django-project/venv/lib/python3.9/site-packages/django/template/base.py", line 958, in render_annotated
[Tue Mar 15 11:04:10.192464 2022] [wsgi:error] [pid 809976] [remote 46.28.73.122:31930]     return self.render(context)
[Tue Mar 15 11:04:10.192478 2022] [wsgi:error] [pid 809976] [remote 46.28.73.122:31930]   File "/django-project/venv/lib/python3.9/site-packages/django/template/loader_tags.py", line 132, in render
[Tue Mar 15 11:04:10.192492 2022] [wsgi:error] [pid 809976] [remote 46.28.73.122:31930]     compiled_parent = self.get_parent(context)
[Tue Mar 15 11:04:10.192506 2022] [wsgi:error] [pid 809976] [remote 46.28.73.122:31930]   File "/django-project/venv/lib/python3.9/site-packages/django/template/loader_tags.py", line 129, in get_parent
[Tue Mar 15 11:04:10.192521 2022] [wsgi:error] [pid 809976] [remote 46.28.73.122:31930]     return self.find_template(parent, context)
[Tue Mar 15 11:04:10.192535 2022] [wsgi:error] [pid 809976] [remote 46.28.73.122:31930]   File "/django-project/venv/lib/python3.9/site-packages/django/template/loader_tags.py", line 107, in find_template
[Tue Mar 15 11:04:10.192549 2022] [wsgi:error] [pid 809976] [remote 46.28.73.122:31930]     template, origin = context.template.engine.find_template(
[Tue Mar 15 11:04:10.192563 2022] [wsgi:error] [pid 809976] [remote 46.28.73.122:31930]   File "/django-project/venv/lib/python3.9/site-packages/django/template/engine.py", line 162, in find_template
[Tue Mar 15 11:04:10.192577 2022] [wsgi:error] [pid 809976] [remote 46.28.73.122:31930]     raise TemplateDoesNotExist(name, tried=tried)
[Tue Mar 15 11:04:10.192591 2022] [wsgi:error] [pid 809976] [remote 46.28.73.122:31930] django.template.exceptions.TemplateDoesNotExist: blog/base.html 
[Tue Mar 15 11:04:10.192606 2022] [wsgi:error] [pid 809976] [remote 46.28.73.122:31930] 
[Tue Mar 15 11:04:10.192619 2022] [wsgi:error] [pid 809976] [remote 46.28.73.122:31930] The above exception was the direct cause of the following exception:
[Tue Mar 15 11:04:10.192633 2022] [wsgi:error] [pid 809976] [remote 46.28.73.122:31930] 
[Tue Mar 15 11:04:10.192647 2022] [wsgi:error] [pid 809976] [remote 46.28.73.122:31930] Traceback (most recent call last):
[Tue Mar 15 11:04:10.192674 2022] [wsgi:error] [pid 809976] [remote 46.28.73.122:31930]   File "/django-project/venv/lib/python3.9/site-packages/django/core/handlers/exception.py", line 55, in inner
[Tue Mar 15 11:04:10.192689 2022] [wsgi:error] [pid 809976] [remote 46.28.73.122:31930]     response = get_response(request)
[Tue Mar 15 11:04:10.192703 2022] [wsgi:error] [pid 809976] [remote 46.28.73.122:31930]   File "/django-project/venv/lib/python3.9/site-packages/django/core/handlers/base.py", line 220, in _get_response
[Tue Mar 15 11:04:10.192717 2022] [wsgi:error] [pid 809976] [remote 46.28.73.122:31930]     response = response.render()
[Tue Mar 15 11:04:10.192731 2022] [wsgi:error] [pid 809976] [remote 46.28.73.122:31930]   File "/django-project/venv/lib/python3.9/site-packages/django/template/response.py", line 114, in render
[Tue Mar 15 11:04:10.192745 2022] [wsgi:error] [pid 809976] [remote 46.28.73.122:31930]     self.content = self.rendered_content
[Tue Mar 15 11:04:10.192760 2022] [wsgi:error] [pid 809976] [remote 46.28.73.122:31930]   File "/django-project/venv/lib/python3.9/site-packages/django/template/response.py", line 92, in rendered_content
[Tue Mar 15 11:04:10.192774 2022] [wsgi:error] [pid 809976] [remote 46.28.73.122:31930]     return template.render(context, self._request)
[Tue Mar 15 11:04:10.192788 2022] [wsgi:error] [pid 809976] [remote 46.28.73.122:31930]   File "/django-project/venv/lib/python3.9/site-packages/django/template/backends/django.py", line 64, in render
[Tue Mar 15 11:04:10.192802 2022] [wsgi:error] [pid 809976] [remote 46.28.73.122:31930]     reraise(exc, self.backend)
[Tue Mar 15 11:04:10.192816 2022] [wsgi:error] [pid 809976] [remote 46.28.73.122:31930]   File "/django-project/venv/lib/python3.9/site-packages/django/template/backends/django.py", line 85, in reraise
[Tue Mar 15 11:04:10.192831 2022] [wsgi:error] [pid 809976] [remote 46.28.73.122:31930]     raise new from exc
[Tue Mar 15 11:04:10.192845 2022] [wsgi:error] [pid 809976] [remote 46.28.73.122:31930] django.template.exceptions.TemplateDoesNotExist: blog/base.html 
[Tue Mar 15 11:04:10.351667 2022] [wsgi:error] [pid 809976] [remote 46.28.73.122:31931] Not Found: /favicon.ico
[Tue Mar 15 11:16:35.068235 2022] [wsgi:error] [pid 810444] [remote 46.28.73.122:32084] Not Found: /assets/favicon.ico
[Tue Mar 15 11:16:39.012202 2022] [wsgi:error] [pid 810444] [remote 46.28.73.122:32087] Not Found: /media/images/3389dec93bebb6f44619d529ba79efff.jpg
[Tue Mar 15 11:16:39.232506 2022] [wsgi:error] [pid 810444] [remote 46.28.73.122:32087] Not Found: /article/assets/favicon.ico
[Tue Mar 15 11:16:42.387141 2022] [wsgi:error] [pid 810444] [remote 46.28.73.122:32087] Internal Server Error: /category/mikrotik
[Tue Mar 15 11:16:42.387203 2022] [wsgi:error] [pid 810444] [remote 46.28.73.122:32087] Traceback (most recent call last):
[Tue Mar 15 11:16:42.387219 2022] [wsgi:error] [pid 810444] [remote 46.28.73.122:32087]   File "/django-project/venv/lib/python3.9/site-packages/django/template/backends/django.py", line 62, in render
[Tue Mar 15 11:16:42.387234 2022] [wsgi:error] [pid 810444] [remote 46.28.73.122:32087]     return self.template.render(context)
[Tue Mar 15 11:16:42.387248 2022] [wsgi:error] [pid 810444] [remote 46.28.73.122:32087]   File "/django-project/venv/lib/python3.9/site-packages/django/template/base.py", line 175, in render
[Tue Mar 15 11:16:42.387263 2022] [wsgi:error] [pid 810444] [remote 46.28.73.122:32087]     return self._render(context)
[Tue Mar 15 11:16:42.387277 2022] [wsgi:error] [pid 810444] [remote 46.28.73.122:32087]   File "/django-project/venv/lib/python3.9/site-packages/django/template/base.py", line 167, in _render
[Tue Mar 15 11:16:42.387292 2022] [wsgi:error] [pid 810444] [remote 46.28.73.122:32087]     return self.nodelist.render(context)
[Tue Mar 15 11:16:42.387306 2022] [wsgi:error] [pid 810444] [remote 46.28.73.122:32087]   File "/django-project/venv/lib/python3.9/site-packages/django/template/base.py", line 1000, in render
[Tue Mar 15 11:16:42.387321 2022] [wsgi:error] [pid 810444] [remote 46.28.73.122:32087]     return SafeString("".join([node.render_annotated(context) for node in self]))
[Tue Mar 15 11:16:42.387364 2022] [wsgi:error] [pid 810444] [remote 46.28.73.122:32087]   File "/django-project/venv/lib/python3.9/site-packages/django/template/base.py", line 1000, in <listcomp>
[Tue Mar 15 11:16:42.387379 2022] [wsgi:error] [pid 810444] [remote 46.28.73.122:32087]     return SafeString("".join([node.render_annotated(context) for node in self]))
[Tue Mar 15 11:16:42.387393 2022] [wsgi:error] [pid 810444] [remote 46.28.73.122:32087]   File "/django-project/venv/lib/python3.9/site-packages/django/template/base.py", line 958, in render_annotated
[Tue Mar 15 11:16:42.387408 2022] [wsgi:error] [pid 810444] [remote 46.28.73.122:32087]     return self.render(context)
[Tue Mar 15 11:16:42.387422 2022] [wsgi:error] [pid 810444] [remote 46.28.73.122:32087]   File "/django-project/venv/lib/python3.9/site-packages/django/template/loader_tags.py", line 132, in render
[Tue Mar 15 11:16:42.387436 2022] [wsgi:error] [pid 810444] [remote 46.28.73.122:32087]     compiled_parent = self.get_parent(context)
[Tue Mar 15 11:16:42.387451 2022] [wsgi:error] [pid 810444] [remote 46.28.73.122:32087]   File "/django-project/venv/lib/python3.9/site-packages/django/template/loader_tags.py", line 129, in get_parent
[Tue Mar 15 11:16:42.387465 2022] [wsgi:error] [pid 810444] [remote 46.28.73.122:32087]     return self.find_template(parent, context)
[Tue Mar 15 11:16:42.387479 2022] [wsgi:error] [pid 810444] [remote 46.28.73.122:32087]   File "/django-project/venv/lib/python3.9/site-packages/django/template/loader_tags.py", line 107, in find_template
[Tue Mar 15 11:16:42.387494 2022] [wsgi:error] [pid 810444] [remote 46.28.73.122:32087]     template, origin = context.template.engine.find_template(
[Tue Mar 15 11:16:42.387508 2022] [wsgi:error] [pid 810444] [remote 46.28.73.122:32087]   File "/django-project/venv/lib/python3.9/site-packages/django/template/engine.py", line 162, in find_template
[Tue Mar 15 11:16:42.387523 2022] [wsgi:error] [pid 810444] [remote 46.28.73.122:32087]     raise TemplateDoesNotExist(name, tried=tried)
[Tue Mar 15 11:16:42.387537 2022] [wsgi:error] [pid 810444] [remote 46.28.73.122:32087] django.template.exceptions.TemplateDoesNotExist: blog/base.html 
[Tue Mar 15 11:16:42.387551 2022] [wsgi:error] [pid 810444] [remote 46.28.73.122:32087] 
[Tue Mar 15 11:16:42.387565 2022] [wsgi:error] [pid 810444] [remote 46.28.73.122:32087] The above exception was the direct cause of the following exception:
[Tue Mar 15 11:16:42.387579 2022] [wsgi:error] [pid 810444] [remote 46.28.73.122:32087] 
[Tue Mar 15 11:16:42.387593 2022] [wsgi:error] [pid 810444] [remote 46.28.73.122:32087] Traceback (most recent call last):
[Tue Mar 15 11:16:42.387607 2022] [wsgi:error] [pid 810444] [remote 46.28.73.122:32087]   File "/django-project/venv/lib/python3.9/site-packages/django/core/handlers/exception.py", line 55, in inner
[Tue Mar 15 11:16:42.387622 2022] [wsgi:error] [pid 810444] [remote 46.28.73.122:32087]     response = get_response(request)
[Tue Mar 15 11:16:42.387636 2022] [wsgi:error] [pid 810444] [remote 46.28.73.122:32087]   File "/django-project/venv/lib/python3.9/site-packages/django/core/handlers/base.py", line 220, in _get_response
[Tue Mar 15 11:16:42.387651 2022] [wsgi:error] [pid 810444] [remote 46.28.73.122:32087]     response = response.render()
[Tue Mar 15 11:16:42.387665 2022] [wsgi:error] [pid 810444] [remote 46.28.73.122:32087]   File "/django-project/venv/lib/python3.9/site-packages/django/template/response.py", line 114, in render
[Tue Mar 15 11:16:42.387679 2022] [wsgi:error] [pid 810444] [remote 46.28.73.122:32087]     self.content = self.rendered_content
[Tue Mar 15 11:16:42.387693 2022] [wsgi:error] [pid 810444] [remote 46.28.73.122:32087]   File "/django-project/venv/lib/python3.9/site-packages/django/template/response.py", line 92, in rendered_content
[Tue Mar 15 11:16:42.387708 2022] [wsgi:error] [pid 810444] [remote 46.28.73.122:32087]     return template.render(context, self._request)
[Tue Mar 15 11:16:42.387743 2022] [wsgi:error] [pid 810444] [remote 46.28.73.122:32087]   File "/django-project/venv/lib/python3.9/site-packages/django/template/backends/django.py", line 64, in render
[Tue Mar 15 11:16:42.387757 2022] [wsgi:error] [pid 810444] [remote 46.28.73.122:32087]     reraise(exc, self.backend)
[Tue Mar 15 11:16:42.387772 2022] [wsgi:error] [pid 810444] [remote 46.28.73.122:32087]   File "/django-project/venv/lib/python3.9/site-packages/django/template/backends/django.py", line 85, in reraise
[Tue Mar 15 11:16:42.387786 2022] [wsgi:error] [pid 810444] [remote 46.28.73.122:32087]     raise new from exc
[Tue Mar 15 11:16:42.387800 2022] [wsgi:error] [pid 810444] [remote 46.28.73.122:32087] django.template.exceptions.TemplateDoesNotExist: blog/base.html 
[Tue Mar 15 11:16:44.681935 2022] [wsgi:error] [pid 810444] [remote 46.28.73.122:32088] Not Found: /favicon.ico
[Tue Mar 15 11:16:51.293526 2022] [wsgi:error] [pid 810444] [remote 46.28.73.122:32089] Internal Server Error: /category/virtualization
[Tue Mar 15 11:16:51.293594 2022] [wsgi:error] [pid 810444] [remote 46.28.73.122:32089] Traceback (most recent call last):
[Tue Mar 15 11:16:51.293610 2022] [wsgi:error] [pid 810444] [remote 46.28.73.122:32089]   File "/django-project/venv/lib/python3.9/site-packages/django/template/backends/django.py", line 62, in render
[Tue Mar 15 11:16:51.293625 2022] [wsgi:error] [pid 810444] [remote 46.28.73.122:32089]     return self.template.render(context)
[Tue Mar 15 11:16:51.293640 2022] [wsgi:error] [pid 810444] [remote 46.28.73.122:32089]   File "/django-project/venv/lib/python3.9/site-packages/django/template/base.py", line 175, in render
[Tue Mar 15 11:16:51.293654 2022] [wsgi:error] [pid 810444] [remote 46.28.73.122:32089]     return self._render(context)
[Tue Mar 15 11:16:51.293668 2022] [wsgi:error] [pid 810444] [remote 46.28.73.122:32089]   File "/django-project/venv/lib/python3.9/site-packages/django/template/base.py", line 167, in _render
[Tue Mar 15 11:16:51.293682 2022] [wsgi:error] [pid 810444] [remote 46.28.73.122:32089]     return self.nodelist.render(context)
[Tue Mar 15 11:16:51.293696 2022] [wsgi:error] [pid 810444] [remote 46.28.73.122:32089]   File "/django-project/venv/lib/python3.9/site-packages/django/template/base.py", line 1000, in render
[Tue Mar 15 11:16:51.293711 2022] [wsgi:error] [pid 810444] [remote 46.28.73.122:32089]     return SafeString("".join([node.render_annotated(context) for node in self]))
[Tue Mar 15 11:16:51.293725 2022] [wsgi:error] [pid 810444] [remote 46.28.73.122:32089]   File "/django-project/venv/lib/python3.9/site-packages/django/template/base.py", line 1000, in <listcomp>
[Tue Mar 15 11:16:51.293739 2022] [wsgi:error] [pid 810444] [remote 46.28.73.122:32089]     return SafeString("".join([node.render_annotated(context) for node in self]))
[Tue Mar 15 11:16:51.293754 2022] [wsgi:error] [pid 810444] [remote 46.28.73.122:32089]   File "/django-project/venv/lib/python3.9/site-packages/django/template/base.py", line 958, in render_annotated
[Tue Mar 15 11:16:51.293768 2022] [wsgi:error] [pid 810444] [remote 46.28.73.122:32089]     return self.render(context)
[Tue Mar 15 11:16:51.293782 2022] [wsgi:error] [pid 810444] [remote 46.28.73.122:32089]   File "/django-project/venv/lib/python3.9/site-packages/django/template/loader_tags.py", line 132, in render
[Tue Mar 15 11:16:51.293796 2022] [wsgi:error] [pid 810444] [remote 46.28.73.122:32089]     compiled_parent = self.get_parent(context)
[Tue Mar 15 11:16:51.293810 2022] [wsgi:error] [pid 810444] [remote 46.28.73.122:32089]   File "/django-project/venv/lib/python3.9/site-packages/django/template/loader_tags.py", line 129, in get_parent
[Tue Mar 15 11:16:51.293825 2022] [wsgi:error] [pid 810444] [remote 46.28.73.122:32089]     return self.find_template(parent, context)
[Tue Mar 15 11:16:51.293839 2022] [wsgi:error] [pid 810444] [remote 46.28.73.122:32089]   File "/django-project/venv/lib/python3.9/site-packages/django/template/loader_tags.py", line 107, in find_template
[Tue Mar 15 11:16:51.293853 2022] [wsgi:error] [pid 810444] [remote 46.28.73.122:32089]     template, origin = context.template.engine.find_template(
[Tue Mar 15 11:16:51.293903 2022] [wsgi:error] [pid 810444] [remote 46.28.73.122:32089]   File "/django-project/venv/lib/python3.9/site-packages/django/template/engine.py", line 162, in find_template
[Tue Mar 15 11:16:51.293918 2022] [wsgi:error] [pid 810444] [remote 46.28.73.122:32089]     raise TemplateDoesNotExist(name, tried=tried)
[Tue Mar 15 11:16:51.293931 2022] [wsgi:error] [pid 810444] [remote 46.28.73.122:32089] django.template.exceptions.TemplateDoesNotExist: blog/base.html 
[Tue Mar 15 11:16:51.293946 2022] [wsgi:error] [pid 810444] [remote 46.28.73.122:32089] 
[Tue Mar 15 11:16:51.293959 2022] [wsgi:error] [pid 810444] [remote 46.28.73.122:32089] The above exception was the direct cause of the following exception:
[Tue Mar 15 11:16:51.293973 2022] [wsgi:error] [pid 810444] [remote 46.28.73.122:32089] 
[Tue Mar 15 11:16:51.293987 2022] [wsgi:error] [pid 810444] [remote 46.28.73.122:32089] Traceback (most recent call last):
[Tue Mar 15 11:16:51.294001 2022] [wsgi:error] [pid 810444] [remote 46.28.73.122:32089]   File "/django-project/venv/lib/python3.9/site-packages/django/core/handlers/exception.py", line 55, in inner
[Tue Mar 15 11:16:51.294015 2022] [wsgi:error] [pid 810444] [remote 46.28.73.122:32089]     response = get_response(request)
[Tue Mar 15 11:16:51.294029 2022] [wsgi:error] [pid 810444] [remote 46.28.73.122:32089]   File "/django-project/venv/lib/python3.9/site-packages/django/core/handlers/base.py", line 220, in _get_response
[Tue Mar 15 11:16:51.294044 2022] [wsgi:error] [pid 810444] [remote 46.28.73.122:32089]     response = response.render()
[Tue Mar 15 11:16:51.294057 2022] [wsgi:error] [pid 810444] [remote 46.28.73.122:32089]   File "/django-project/venv/lib/python3.9/site-packages/django/template/response.py", line 114, in render
[Tue Mar 15 11:16:51.294072 2022] [wsgi:error] [pid 810444] [remote 46.28.73.122:32089]     self.content = self.rendered_content
[Tue Mar 15 11:16:51.294086 2022] [wsgi:error] [pid 810444] [remote 46.28.73.122:32089]   File "/django-project/venv/lib/python3.9/site-packages/django/template/response.py", line 92, in rendered_content
[Tue Mar 15 11:16:51.294100 2022] [wsgi:error] [pid 810444] [remote 46.28.73.122:32089]     return template.render(context, self._request)
[Tue Mar 15 11:16:51.294114 2022] [wsgi:error] [pid 810444] [remote 46.28.73.122:32089]   File "/django-project/venv/lib/python3.9/site-packages/django/template/backends/django.py", line 64, in render
[Tue Mar 15 11:16:51.294128 2022] [wsgi:error] [pid 810444] [remote 46.28.73.122:32089]     reraise(exc, self.backend)
[Tue Mar 15 11:16:51.294142 2022] [wsgi:error] [pid 810444] [remote 46.28.73.122:32089]   File "/django-project/venv/lib/python3.9/site-packages/django/template/backends/django.py", line 85, in reraise
[Tue Mar 15 11:16:51.294156 2022] [wsgi:error] [pid 810444] [remote 46.28.73.122:32089]     raise new from exc
[Tue Mar 15 11:16:51.294170 2022] [wsgi:error] [pid 810444] [remote 46.28.73.122:32089] django.template.exceptions.TemplateDoesNotExist: blog/base.html 
[Tue Mar 15 11:17:36.889591 2022] [wsgi:error] [pid 810444] [remote 46.28.73.122:32090] Not Found: /media/images/3389dec93bebb6f44619d529ba79efff.jpg
[Tue Mar 15 11:17:36.990833 2022] [wsgi:error] [pid 810444] [remote 46.28.73.122:32090] Not Found: /article/assets/favicon.ico
[Tue Mar 15 11:17:38.396910 2022] [wsgi:error] [pid 810444] [remote 46.28.73.122:32105] Not Found: /category/assets/favicon.ico
[Tue Mar 15 11:17:56.652141 2022] [wsgi:error] [pid 810444] [remote 46.28.73.122:32162] Not Found: /assets/favicon.ico
[Tue Mar 15 11:17:58.325425 2022] [wsgi:error] [pid 810444] [remote 46.28.73.122:32164] Not Found: /media/images/3389dec93bebb6f44619d529ba79efff.jpg
[Tue Mar 15 11:17:58.419295 2022] [wsgi:error] [pid 810444] [remote 46.28.73.122:32164] Not Found: /article/assets/favicon.ico
[Tue Mar 15 11:18:00.316578 2022] [wsgi:error] [pid 810444] [remote 46.28.73.122:32164] Not Found: /assets/favicon.ico
[Tue Mar 15 11:22:34.164901 2022] [wsgi:error] [pid 810444] [remote 46.28.73.122:32238] Not Found: /category/assets/favicon.ico
[Tue Mar 15 11:22:36.447514 2022] [wsgi:error] [pid 810444] [remote 46.28.73.122:32240] Not Found: /assets/favicon.ico
[Tue Mar 15 11:48:49.549361 2022] [wsgi:error] [pid 811074] [remote 46.28.73.122:32813] Not Found: /media/images/3389dec93bebb6f44619d529ba79efff.jpg
[Tue Mar 15 11:48:49.788130 2022] [wsgi:error] [pid 811074] [remote 46.28.73.122:32819] Not Found: /favicon.ico
[Tue Mar 15 11:48:55.687146 2022] [wsgi:error] [pid 811074] [remote 46.28.73.122:32822] Not Found: /media/images/3389dec93bebb6f44619d529ba79efff.jpg
[Tue Mar 15 11:48:55.929410 2022] [wsgi:error] [pid 811074] [remote 46.28.73.122:32827] Not Found: /favicon.ico
[Tue Mar 15 11:49:06.529836 2022] [wsgi:error] [pid 811074] [remote 46.28.73.122:32838] Not Found: /media/images/3389dec93bebb6f44619d529ba79efff.jpg
[Tue Mar 15 14:51:46.598479 2022] [wsgi:error] [pid 811189] [remote 46.28.73.122:34582] Not Found: /article/assets/favicon.ico
[Tue Mar 15 15:00:36.123554 2022] [wsgi:error] [pid 811189] [remote 121.206.153.207:25185] Not Found: /shell
[Tue Mar 15 15:24:42.921183 2022] [wsgi:error] [pid 811189] [remote 109.237.103.123:45610] Not Found: /.env
[Tue Mar 15 15:31:56.365330 2022] [wsgi:error] [pid 811189] [remote 192.241.212.162:32850] Not Found: /portal/redlion
[Tue Mar 15 16:09:05.672381 2022] [wsgi:error] [pid 811189] [remote 85.15.7.131:1891] Session data corrupted
[Tue Mar 15 16:09:37.291474 2022] [wsgi:error] [pid 811189] [remote 85.15.7.131:1943] Not Found: /assets/favicon.ico
[Tue Mar 15 16:10:38.116451 2022] [wsgi:error] [pid 811189] [remote 192.241.225.72:55814] Not Found: /hudson
[Tue Mar 15 16:12:03.489139 2022] [wsgi:error] [pid 811189] [remote 85.15.7.131:1843] Session data corrupted
[Tue Mar 15 17:04:15.303986 2022] [wsgi:error] [pid 811189] [remote 184.94.240.88:9189] Not Found: /category/voip/
[Tue Mar 15 17:04:16.057244 2022] [wsgi:error] [pid 811189] [remote 184.94.240.88:47293] Not Found: /article/first/
[Tue Mar 15 17:16:58.839309 2022] [wsgi:error] [pid 811189] [remote 45.137.21.141:43066] Not Found: /dispatch.asp
[Tue Mar 15 18:12:56.824115 2022] [wsgi:error] [pid 811189] [remote 184.94.240.88:18570] Not Found: /category/voip/
[Tue Mar 15 18:12:58.953734 2022] [wsgi:error] [pid 811189] [remote 184.94.240.88:44626] Not Found: /article/first/
[Tue Mar 15 18:13:01.065803 2022] [wsgi:error] [pid 811189] [remote 184.94.240.88:58904] Not Found: /category/cisco/
[Tue Mar 15 18:44:58.941600 2022] [wsgi:error] [pid 811189] [remote 37.0.8.109:53794] Not Found: /config/getuser
[Tue Mar 15 19:28:16.417525 2022] [wsgi:error] [pid 811189] [remote 172.105.77.209:47169] Not Found: /0bef
[Tue Mar 15 20:58:40.941371 2022] [wsgi:error] [pid 811189] [remote 184.94.240.88:17673] Not Found: /category/voip/
[Tue Mar 15 20:58:42.016047 2022] [wsgi:error] [pid 811189] [remote 184.94.240.88:48720] Not Found: /article/first/
[Tue Mar 15 21:21:27.783801 2022] [wsgi:error] [pid 811189] [remote 156.146.63.138:45810] Not Found: /backup/wallet.dat
[Tue Mar 15 21:21:42.859365 2022] [wsgi:error] [pid 811189] [remote 156.146.63.138:47978] Not Found: /wallets/wallet.dat
[Tue Mar 15 21:22:34.070251 2022] [wsgi:error] [pid 811189] [remote 156.146.63.138:55238] Not Found: /bitcoin/wallet.dat
[Tue Mar 15 21:23:09.690205 2022] [wsgi:error] [pid 811189] [remote 156.146.63.138:60072] Not Found: /backups/wallet.dat
[Tue Mar 15 21:24:01.965894 2022] [wsgi:error] [pid 811189] [remote 156.146.63.138:38510] Not Found: /wallet.dat
[Tue Mar 15 21:24:09.255188 2022] [wsgi:error] [pid 811189] [remote 156.146.63.138:39744] Not Found: /Bitcoin/wallet.dat
[Tue Mar 15 21:24:56.250107 2022] [wsgi:error] [pid 811189] [remote 156.146.63.138:46498] Not Found: /wallet/wallet.dat
[Tue Mar 15 21:25:40.404011 2022] [wsgi:error] [pid 811189] [remote 156.146.63.138:52268] Not Found: /bitcoin/backup/wallet.dat
[Tue Mar 15 21:46:06.312374 2022] [wsgi:error] [pid 811189] [remote 212.102.37.109:34160] Not Found: /backup/bitcoin/wallet.dat
[Tue Mar 15 22:20:33.930202 2022] [wsgi:error] [pid 811189] [remote 109.237.103.9:56438] Not Found: /.env
[Tue Mar 15 22:27:21.236956 2022] [wsgi:error] [pid 811189] [remote 45.137.21.141:40164] Not Found: /doc/script/lib/seajs/config/sea-config.js
[Tue Mar 15 22:57:12.835139 2022] [wsgi:error] [pid 811189] [remote 85.15.7.131:1884] Not Found: /assets/favicon.ico
[Tue Mar 15 22:58:26.592602 2022] [wsgi:error] [pid 811189] [remote 85.15.7.131:1848] Not Found: /assets/favicon.ico
[Tue Mar 15 22:58:30.819821 2022] [wsgi:error] [pid 811189] [remote 85.15.7.131:1840] Not Found: /favicon.ico
[Tue Mar 15 23:02:41.615906 2022] [wsgi:error] [pid 821056] [remote 85.15.7.131:1899] Not Found: /admidasdasd
[Tue Mar 15 23:35:21.539209 2022] [wsgi:error] [pid 821484] [remote 85.15.7.131:1884] Not Found: /article/assets/favicon.ico
[Tue Mar 15 23:35:23.836893 2022] [wsgi:error] [pid 821484] [remote 85.15.7.131:1884] Not Found: /category/assets/favicon.ico
[Wed Mar 16 00:41:08.715164 2022] [wsgi:error] [pid 821779] [remote 20.206.76.209:56549] Not Found: /wp-includes/wlwmanifest.xml
[Wed Mar 16 00:41:09.060491 2022] [wsgi:error] [pid 821779] [remote 20.206.76.209:56549] Not Found: /xmlrpc.php
[Wed Mar 16 00:41:09.821726 2022] [wsgi:error] [pid 821779] [remote 20.206.76.209:56549] Not Found: /blog/wp-includes/wlwmanifest.xml
[Wed Mar 16 00:41:10.162325 2022] [wsgi:error] [pid 821779] [remote 20.206.76.209:56549] Not Found: /web/wp-includes/wlwmanifest.xml
[Wed Mar 16 00:41:10.518543 2022] [wsgi:error] [pid 821779] [remote 20.206.76.209:56549] Not Found: /wordpress/wp-includes/wlwmanifest.xml
[Wed Mar 16 00:41:10.881648 2022] [wsgi:error] [pid 821779] [remote 20.206.76.209:56549] Not Found: /website/wp-includes/wlwmanifest.xml
[Wed Mar 16 00:41:11.219525 2022] [wsgi:error] [pid 821779] [remote 20.206.76.209:56549] Not Found: /wp/wp-includes/wlwmanifest.xml
[Wed Mar 16 00:41:11.556197 2022] [wsgi:error] [pid 821779] [remote 20.206.76.209:56549] Not Found: /news/wp-includes/wlwmanifest.xml
[Wed Mar 16 00:41:11.893846 2022] [wsgi:error] [pid 821779] [remote 20.206.76.209:56549] Not Found: /2018/wp-includes/wlwmanifest.xml
[Wed Mar 16 00:41:12.238457 2022] [wsgi:error] [pid 821779] [remote 20.206.76.209:56549] Not Found: /2019/wp-includes/wlwmanifest.xml
[Wed Mar 16 00:41:12.575970 2022] [wsgi:error] [pid 821779] [remote 20.206.76.209:56549] Not Found: /shop/wp-includes/wlwmanifest.xml
[Wed Mar 16 00:41:12.912674 2022] [wsgi:error] [pid 821779] [remote 20.206.76.209:56549] Not Found: /wp1/wp-includes/wlwmanifest.xml
[Wed Mar 16 00:41:13.250517 2022] [wsgi:error] [pid 821779] [remote 20.206.76.209:56549] Not Found: /test/wp-includes/wlwmanifest.xml
[Wed Mar 16 00:41:13.907909 2022] [wsgi:error] [pid 821779] [remote 20.206.76.209:56549] Not Found: /wp2/wp-includes/wlwmanifest.xml
[Wed Mar 16 00:41:14.279886 2022] [wsgi:error] [pid 821779] [remote 20.206.76.209:56549] Not Found: /site/wp-includes/wlwmanifest.xml
[Wed Mar 16 00:41:14.619904 2022] [wsgi:error] [pid 821779] [remote 20.206.76.209:56549] Not Found: /cms/wp-includes/wlwmanifest.xml
[Wed Mar 16 00:41:14.961585 2022] [wsgi:error] [pid 821779] [remote 20.206.76.209:56549] Not Found: /sito/wp-includes/wlwmanifest.xml
[Wed Mar 16 01:34:43.036457 2022] [wsgi:error] [pid 821779] [remote 184.94.240.88:65288] Not Found: /article/first/
[Wed Mar 16 01:34:46.009966 2022] [wsgi:error] [pid 821779] [remote 184.94.240.88:36992] Not Found: /category/voip/
[Wed Mar 16 02:50:51.983736 2022] [wsgi:error] [pid 821779] [remote 45.137.21.141:57780] Not Found: /dispatch.asp
[Wed Mar 16 03:15:07.168370 2022] [wsgi:error] [pid 821779] [remote 31.210.20.109:57404] Not Found: /HNAP1/
[Wed Mar 16 04:57:58.234269 2022] [wsgi:error] [pid 821779] [remote 45.146.165.37:56970] Not Found: /vendor/phpunit/phpunit/src/Util/PHP/eval-stdin.php
[Wed Mar 16 05:31:34.461664 2022] [wsgi:error] [pid 821779] [remote 45.137.21.166:57040] Not Found: /config/getuser
[Wed Mar 16 05:44:16.307156 2022] [wsgi:error] [pid 821779] [remote 45.146.165.37:37088] Not Found: /vendor/phpunit/phpunit/src/Util/PHP/eval-stdin.php
[Wed Mar 16 06:08:00.499207 2022] [wsgi:error] [pid 821779] [remote 192.168.1.200:51596] Not Found: /index.php/204
[Wed Mar 16 06:23:01.051371 2022] [wsgi:error] [pid 821779] [remote 192.168.1.200:52484] Not Found: /index.php/204
[Wed Mar 16 06:27:57.228149 2022] [wsgi:error] [pid 821779] [remote 45.146.165.37:50764] Not Found: /solr/admin/info/system
[Wed Mar 16 06:41:22.942764 2022] [wsgi:error] [pid 821779] [remote 45.146.165.37:35824] Not Found: /index.php
[Wed Mar 16 06:46:36.725066 2022] [wsgi:error] [pid 821779] [remote 23.95.100.141:57086] Not Found: /boaform/admin/formLogin
[Wed Mar 16 06:46:59.863484 2022] [wsgi:error] [pid 821779] [remote 45.137.21.141:56086] Not Found: /dispatch.asp
[Wed Mar 16 06:52:51.124522 2022] [wsgi:error] [pid 821779] [remote 134.122.134.136:38248] Not Found: /assets/favicon.ico
[Wed Mar 16 06:52:51.857699 2022] [wsgi:error] [pid 821779] [remote 134.122.134.136:38392] Not Found: /robots.txt
[Wed Mar 16 06:52:55.690549 2022] [wsgi:error] [pid 821779] [remote 134.122.134.136:38580] Not Found: /sitemap.xml
[Wed Mar 16 07:07:14.716255 2022] [wsgi:error] [pid 821779] [remote 23.251.102.82:40512] Not Found: /showLogin.cc
[Wed Mar 16 07:25:54.933450 2022] [wsgi:error] [pid 821779] [remote 89.47.143.204:53393] Not Found: /assets/favicon.ico
[Wed Mar 16 07:26:01.492383 2022] [wsgi:error] [pid 821779] [remote 89.47.143.204:43960] Not Found: /category/assets/favicon.ico
[Wed Mar 16 07:26:25.764969 2022] [wsgi:error] [pid 821779] [remote 89.47.143.204:21480] Not Found: /article/assets/favicon.ico
[Wed Mar 16 07:37:38.837083 2022] [wsgi:error] [pid 828395] [remote 46.28.73.122:43200] Not Found: /assets/favicon.ico
[Wed Mar 16 07:37:42.539845 2022] [wsgi:error] [pid 828395] [remote 46.28.73.122:43222] Not Found: /favicon.ico
[Wed Mar 16 07:38:44.630137 2022] [wsgi:error] [pid 828395] [remote 46.28.73.122:43297] Not Found: /favicon.ico
[Wed Mar 16 07:39:03.158546 2022] [wsgi:error] [pid 828395] [remote 46.28.73.122:43304] Not Found: /assets/favicon.ico
[Wed Mar 16 07:50:31.753474 2022] [wsgi:error] [pid 828395] [remote 46.28.73.122:43419] Not Found: /favicon.ico
[Wed Mar 16 08:14:35.553871 2022] [wsgi:error] [pid 828395] [remote 23.251.102.74:55148] Not Found: /webfig/
[Wed Mar 16 08:30:04.573054 2022] [wsgi:error] [pid 828395] [remote 45.146.165.37:39714] Not Found: /console/
[Wed Mar 16 08:34:22.572460 2022] [wsgi:error] [pid 828395] [remote 46.28.73.122:44153] Not Found: /assets/favicon.ico
[Wed Mar 16 08:34:29.712929 2022] [wsgi:error] [pid 828395] [remote 46.28.73.122:44170] Not Found: /favicon.ico
